<?xml version='1.0'?>

<robot name="FIRSTBOT" >

  <static>false</static>

  <link name='chassis'>
    <pose>0 0 0.1 0 0 0</pose>

    <inertial>
      <mass value="10.0"/>
      <origin xyz="0 0 0.15" rpy=" 0 0 0"/>
      <inertia
        ixx="0.09" ixy="0" ixz="0"
        iyy="0.09" iyz="0"
        izz="0.09"
      />
    </inertial>
  
    <collision name='collision'>
      <geometry>
        <box size="1.0 1.0 .1"/>
      </geometry>
    </collision>
 
    <visual name='chassis_visual'>
      <origin xyz="0 0 0.15" rpy="0 0 0"/>
        <geometry>
          <box size="1.0 1.0 .1"/>
        </geometry>
    </visual>
  </link>


  <link name="left_wheel">
    <collision name="collision">
       <origin xyz="0 0 0" rpy="0 1.5707 1.5707"/>
       <geometry>
          <cylinder radius="0.2" length="0.05"/>
       </geometry>
    </collision>
    <visual name="left_wheel_visual">
       <origin xyz="0 0 0" rpy="0 1.5707 1.5707"/>
       <geometry>
         <cylinder radius="0.2" length="0.05"/>
       </geometry>
    </visual>
    <inertial>
       <origin xyz="0 0 0" rpy="0 1.5707 1.5707"/>
       <mass value="5"/>
       <cylinder_inertia m="5" r="0.2" h="0.05"/>
       <inertia
          ixx="0.051" ixy="0.0" ixz="0.0"
          iyy="0.051" iyz="0.0"
          izz="0.1"/>
    </inertial>
  </link>

  <link name="right_wheel">
    <collision name="collision">
       <origin xyz="0 0 0" rpy="0 1.5707 1.5707"/>
       <geometry>
          <cylinder radius="0.2" length="0.05"/>
       </geometry>
    </collision>
    <visual name="right_wheel_visual">
       <origin xyz="0 0 0" rpy="0 1.5707 1.5707"/>
       <geometry>
         <cylinder radius="0.2" length="0.05"/>
       </geometry>
    </visual>
    <inertial>
       <origin xyz="0 0 0" rpy="0 1.5707 1.5707"/>
       <mass value="5"/>
       <cylinder_inertia m="5" r="0.2" h="0.05"/>
       <inertia
          ixx="0.051" ixy="0.0" ixz="0.0"
          iyy="0.051" iyz="0.0"
          izz="0.1"/>
    </inertial>
  </link>

  <link name="left_back_wheel">
    <collision name="collision">
       <origin xyz="0 0 0" rpy="0 1.5707 1.5707"/>
       <geometry>
          <cylinder radius="0.2" length="0.05"/>
       </geometry>
    </collision>
    <visual name="left_back_wheel_visual">
       <origin xyz="0 0 0" rpy="0 1.5707 1.5707"/>
       <geometry>
         <cylinder radius="0.2" length="0.05"/>
       </geometry>
    </visual>
    <inertial>
       <origin xyz="0 0 0" rpy="0 1.5707 1.5707"/>
       <mass value="5"/>
       <cylinder_inertia m="5" r="0.2" h="0.05"/>
       <inertia
          ixx="0.051" ixy="0.0" ixz="0.0"
          iyy="0.051" iyz="0.0"
          izz="0.1"/>
    </inertial>
  </link>
   
  <link name="right_back_wheel">
    <collision name="collision">
       <origin xyz="0 0 0" rpy="0 1.5707 1.5707"/>
       <geometry>
          <cylinder radius="0.2" length="0.05"/>
       </geometry>
    </collision>
    <visual name="right_back_wheel_visual">
       <origin xyz="0 0 0" rpy="0 1.5707 1.5707"/>
       <geometry>
         <cylinder radius="0.2" length="0.05"/>
       </geometry>
    </visual>
    <inertial>
       <origin xyz="0 0 0" rpy="0 1.5707 1.5707"/>
       <mass value="5"/>
       <cylinder_inertia m="5" r="0.2" h="0.05"/>
       <inertia
          ixx="0.051" ixy="0.0" ixz="0.0"
          iyy="0.051" iyz="0.0"
          izz="0.1"/>
    </inertial>
  </link>

  <joint type="continuous" name="left_wheel_joint">
     <origin xyz="0.4 0.525 0.15" rpy="0 0 0"/>
     <child link="left_wheel"/>
     <parent link="chassis"/>
     <axis xyz="0 1 0" rpy="0 0 0"/>
     <limit effort="100" velocity="100"/>
     <joint_properties damping="1.0" friction="1.0"/>
  </joint>
  

  <joint type="continuous" name="right_wheel_joint">
     <origin xyz="0.4 -0.525 0.15" rpy="0 0 0"/>
     <child link="right_wheel"/>
     <parent link="chassis"/>
     <axis xyz="0 1 0" rpy="0 0 0"/>
     <limit effort="100" velocity="100"/>
     <joint_properties damping="1.0" friction="1.0"/>
  </joint>
   
   <joint type="continuous" name="left_wheel_back_joint">
     <origin xyz="-0.4 0.525 0.15" rpy="0 0 0"/>
     <child link="left_back_wheel"/>
     <parent link="chassis"/>
     <axis xyz="0 1 0" rpy="0 0 0"/>
     <limit effort="100" velocity="100"/>
     <joint_properties damping="1.0" friction="1.0"/>
  </joint>
   

  <joint type="continuous" name="right_wheel_back_joint">
     <origin xyz="-0.4 -0.525 0.15" rpy="0 0 0"/>
     <child link="right_back_wheel"/>
     <parent link="chassis"/>
     <axis xyz="0 1 0" rpy="0 0 0"/>
     <limit effort="100" velocity="100"/>
     <joint_properties damping="1.0" friction="1.0"/>
  </joint>

 <gazebo>
    <plugin name="differential_drive_controller" filename="libgazebo_ros_diff_drive.so">
      
      <alwaysOn>true</alwaysOn>
      <updateRate>10</updateRate>
      <leftJoint>left_wheel_joint</leftJoint>
      <rightJoint>right_wheel_joint</rightJoint>
      <wheelSeparation>0.4</wheelSeparation>
      <wheelDiameter>0.2</wheelDiameter>
      <torque>10</torque>
      <commandTopic>cmd_vel</commandTopic>
      <odometryTopic>odom</odometryTopic>
      <odometryFrame>odom</odometryFrame>
      <robotBaseFrame>chassis</robotBaseFrame>
    </plugin>
  </gazebo>

  <gazebo reference="chassis">
    <material>Gazebo/Orange</material>
  </gazebo>

  <gazebo reference="left_wheel">
    <material>Gazebo/Blue</material>
  </gazebo>

  <gazebo reference="right_wheel">
    <material>Gazebo/Blue</material>
  </gazebo>

  <gazebo reference="left_back_wheel">
    <material>Gazebo</material>
  </gazebo>

  <gazebo reference="right_back_wheel">
    <material>Gazebo</material>
  </gazebo>



</robot>
   





   




  

